# Retry

<table>
 <tr>
    <td>Ограничение времени</td>
    <td>1 c</td>
 </tr>
 <tr>
    <td>Ограничение памяти</td>
    <td>64 Mb</td>
 </tr>
  <tr>
    <td>Ввод</td>
    <td>стандартный ввод или input.txt</td>
 </tr>
  <tr>
    <td>Вывод</td>
    <td>стандартный ввод или input.txt</td>
 </tr>
</table>

Иногда некоторые действия не получается выполнить с первого раза. Например, обращение по сети в сторонний сервис может обернуться неудачей из-за сетевых проблем или перегрузки сервиса. В таких случаях иногда пишут код, который пытается повторить такое действие несколько раз подряд.

Вам надо написать реализацию функции DoWithRetry с таким заголовком:

```
#include <exception>
#include <functional>
#include <optional>

template <typename Result, typename Exception = std::exception>
std::optional<Result> DoWithRetry(std::function<Result()> func,
                                  int retryCount, int sleepTime, bool throwLast);
```

Функция принимает на вход другую функцию без аргументов, возвращающую значение типа Result, количество повторов, таймаут между повторами и флажок throwLast.

Одним из шаблонных параметров функции является тип исключения, на которое функция реагирует. Функция должна вызвать func, и если произошло исключение указанного типа, то вызвать нашу функцию Sleep с параметром sleepTime, а затем повторить попытку (если попытки еще остались). Максимальное количество вызовов func, которое может получиться, равно retryCount + 1. Если на последней попытке происходит исключение указанного типа, и throwLast истинно, этот же объект исключения должен проброситься дальше из функции. Если же throwLast ложно, то надо просто вернуть пустой объект std::optional. Если же вызов func закончился успешно, то надо просто вернуть результат func.

## Примечание
Про std::optional можно прочитать здесь. Если исключение произошло на последней попытке, то после неё «спать» не надо.